Workbook

Sheet Read Me
B2: Team Talent — User Stories & Test Cases Workbook
B3: AI-Powered HR & Talent Management Platform · Client: Mazik Global
B5: Contents
B6: User Stories | C6: One row per user story (140 total) with full requirement detail and an Assigned Developer column at the far right for team allocation.
B7: Test Cases | C7: One row per test case (1,177 total), traceable back to its Story ID, with a Status column to track execution.
B8: Traceability Summary | C8: One row per user story showing test-case coverage counts, pass/fail/not-run breakdown, and the assigned developer — all computed with live formulas.
B9: Team Members | C9: Editable list of developer / QA names. Add your team here — the Assigned Developer dropdown on the User Stories sheet pulls from this list.
B11: How to use it
B12: Filtering | C12: Every data sheet has AutoFilter enabled on its header row — use the dropdown arrows to filter by Phase, Priority, Status, Assigned Developer, etc.
B13: Assigning work | C13: Go to the "User Stories" sheet, scroll to the last column (Assigned Developer), and pick a name from the dropdown for each story. Add more names on the "Team Members" sheet first if needed.
B14: Tracking test execution | C14: On the "Test Cases" sheet, set the Status dropdown to Not Run / Pass / Fail / Blocked as testing progresses — the cell colour updates automatically and the Traceability Summary recalculates.
B15: Frozen headers | C15: Header rows are frozen on every sheet so column titles stay visible while you scroll.
B17: Totals
B18: Total User Stories | C18: 140 (US-001 to US-140)
B19: Total Test Cases | C19: 1177
B20: Phase 2 -- Digital Hiring & Employee Onboarding | C20: 65 user stories
B21: Phase 3 -- Learning, Performance & Talent Management | C21: 45 user stories
B22: Phase 4 -- AI Coaching & Intelligent Assistance | C22: 15 user stories
B23: Phase 5 -- Reporting, Analytics & Executive Dashboards | C23: 15 user stories
B25: Colour Legend — Priority
B26: Critical | C26: Must be delivered first — blocking or core platform functionality.
B27: High | C27: Important for the release; schedule soon after Critical items.
B28: Medium | C28: Standard priority; scheduled in normal sprint order.
B29: Low | C29: Nice-to-have; can slip to a later release if needed.
B31: Colour Legend — Test Case Type
B32: Positive | C32: Valid / happy-path scenario.
B33: Negative | C33: Invalid input or error-handling scenario.
B34: Security | C34: Authorization / access-control scenario.
B35: Boundary | C35: Limit or edge-value scenario.
B37: Colour Legend — Test Status
B38: Not Run
B39: Pass
B40: Fail
B41: Blocked
B43: Generated 14 Jul 2026 · Source: Talent_SaaS_Phase1_US001-US035_Updated.docx

Sheet User Stories
A1: Story ID | B1: Phase | C1: Epic | D1: Feature / Module | E1: Actor | F1: Priority | G1: Pts | H1: User Story (As a / I want / So that) | I1: Description | J1: Acceptance Criteria | K1: Business Rules | L1: Dependencies | M1: Suggested API(s) | N1: Assigned Developer | O1: STATUS
A2: US-001 | B2: Phase 2 -- Digital Hiring & Employee Onboarding | C2: Epic 1: Authentication & Access Management | D2: Authentication & Access Management | E2: Recruiter | F2: Critical | G2: 5 | H2: As a Recruiter, I want to register my account using my official company email so that I can securely access the Talent platform. | I2: The system shall allow recruiters to create a new account by providing their official company email address, full name, phone number, and password. The registration process shall validate all mandatory fields, prevent duplicate accounts, securely store credentials using Supabase Authentication, and send an email verification link. The recruiter account shall remain inactive until the email address has been successfully verified. || Business Value: Ensures only verified recruiters can access the Talent platform while maintaining secure authentication. || Preconditions: Recruiter has access to the registration page.; Recruiter does not already have an account. || Main Flow: Open Registration page.; Enter Full Name.; Enter Company Email.; Enter Phone Number.; Enter Password.; Confirm Password.; Accept Terms & Conditions.; Click Register.; Validate input.; Create account.; Send verification email.; Display success message. || Validation Rules: Email format validation.; Password confirmation must match.; Mandatory fields cannot be empty. || Database: Supabase Auth; MongoDB: Recruiters; MongoDB: AuditLogs | J2: Given valid information, when Register is clicked, then recruiter account is created. • Given duplicate email, when Register is clicked, then duplicate email message is displayed. • Given weak password, when Register is clicked, then registration is blocked. • Given successful registration, then verification email is sent. • Recruiter cannot login until email is verified. | K2: Company email must be unique. • Password minimum 8 characters. • Password must contain uppercase, lowercase, number, and special character. • Email verification mandatory. | L2: None | M2: POST /api/auth/register | N2: Syed Omer Ahmed Shamsi | O2: Dev done
A3: US-002 | B3: Phase 2 -- Digital Hiring & Employee Onboarding | C3: Epic 1: Authentication & Access Management | D3: Authentication & Access Management | E3: Recruiter | F3: Critical | G3: 3 | H3: As a Recruiter, I want to verify my email address so that my account becomes active. | I3: The system shall automatically send a verification email after successful registration. Recruiters shall activate their account by clicking the verification link. || Main Flow: Registration completed.; Verification email sent.; Recruiter clicks verification link.; Token validated.; Account activated.; Success message displayed. || Database: VerificationTokens; Recruiters | J3: Verification email generated. • Token expires after 24 hours. • Expired token displays appropriate message. • Verification activates account. • Token cannot be reused. | K3: Verification link valid for 24 hours. • One-time use only. | L3: None | M3: POST /api/auth/verify-email | N3: Syed Omer Ahmed Shamsi | O3: Dev done
A4: US-003 | B4: Phase 2 -- Digital Hiring & Employee Onboarding | C4: Epic 1: Authentication & Access Management | D4: Authentication & Access Management | E4: Recruiter | F4: Medium | G4: 2 | H4: As a Recruiter, I want to resend my verification email if I did not receive it. | I4: Recruiters may request a new verification email while their account remains inactive. | J4: Verification email resent successfully. • Previous token invalidated. • New token generated. • Success message displayed. | L4: None | M4: POST /api/auth/resend-verification | N4: Taha Iftikhar | O4: Dev done
A5: US-004 | B5: Phase 2 -- Digital Hiring & Employee Onboarding | C5: Epic 1: Authentication & Access Management | D5: Authentication & Access Management | E5: User | F5: Critical | G5: 5 | H5: As a Recruiter, I want to securely login so that I can access my dashboard. | I5: The system shall authenticate recruiters using Supabase Authentication and redirect authenticated users to the Recruiter Dashboard. | J5: Valid login succeeds. • Invalid credentials rejected. • Loading indicator shown. • JWT session created. • Audit log generated. | K5: Maximum 5 failed login attempts. • Account locked for 15 minutes. • API • POST /api/auth/login | L5: None | N5: Taha Iftikhar | O5: Dev done
A6: US-005 | B6: Phase 2 -- Digital Hiring & Employee Onboarding | C6: Epic 1: Authentication & Access Management | D6: Authentication & Access Management | E6: User | F6: Medium | G6: 2 | H6: As a Recruiter, I want my login session remembered so that I don't have to login repeatedly. | I6: Allow persistent login using secure refresh tokens. | J6: Session restored. • Refresh token validated. • Invalid refresh token rejected. | L6: None | N6: Sadaf Ashfaq | O6: Dev done
A7: US-006 | B7: Phase 2 -- Digital Hiring & Employee Onboarding | C7: Epic 1: Authentication & Access Management | D7: Authentication & Access Management | E7: User | F7: High | G7: 3 | H7: As a Recruiter, I want to reset my password if I forget it. | I7: Allow recruiters to request a secure password reset email. | J7: Registered email accepted. • Reset token generated. • Email sent. • Invalid email handled securely. • API • POST /api/auth/forgot-password | L7: None | N7: Sadaf Ashfaq | O7: Dev done
A8: US-007 | B8: Phase 2 -- Digital Hiring & Employee Onboarding | C8: Epic 1: Authentication & Access Management | D8: Authentication & Access Management | E8: User | F8: High | G8: 3 | H8: As a Recruiter, I want to create a new password using a reset link. | I8: Allow recruiters to securely update their password after validating the reset token. | J8: Token validated. • Password updated. • Previous sessions revoked. • Success confirmation shown. | L8: None | N8: Faris Dosani | O8: Dev done
A9: US-008 | B9: Phase 2 -- Digital Hiring & Employee Onboarding | C9: Epic 1: Authentication & Access Management | D9: Authentication & Access Management | E9: User | F9: Medium | G9: 2 | H9: As a Recruiter, I want to logout securely so that my session ends safely. | I9: Terminate active session and revoke authentication tokens. | J9: Session destroyed. • Refresh token revoked. • Redirect to Login page. • Audit log recorded. | L9: None | N9: Faris Dosani | O9: Dev done
A10: US-009 | B10: Phase 2 -- Digital Hiring & Employee Onboarding | C10: Epic 1: Authentication & Access Management | D10: Authentication & Access Management | E10: User | F10: Medium | G10: 2 | H10: As a Recruiter, I want inactive sessions to expire automatically to improve security. | I10: Automatically logout users after configurable inactivity. | J10: Idle timer starts. • Warning displayed before timeout. • Session expires automatically. • Login required again. | L10: None | N10: Aimen Abdullah | O10: Dev done
A11: US-010 | B11: Phase 2 -- Digital Hiring & Employee Onboarding | C11: Epic 1: Authentication & Access Management | D11: Authentication & Access Management | E11: User | F11: Critical | G11: 5 | H11: As a Candidate, I want to register my account after accepting an offer so that I can begin onboarding. | I11: Candidates shall register using the invitation link provided by the recruiter and complete account creation. | J11: Invitation validated. • Candidate account created. • Email verified. • Redirect to onboarding. | L11: None | N11: Aimen Abdullah | O11: Dev done
A12: US-011 | B12: Phase 2 -- Digital Hiring & Employee Onboarding | C12: Epic 1: Authentication & Access Management | D12: Authentication & Access Management | E12: User | F12: Critical | G12: 5 | H12: As a Candidate, I want to securely login so that I can complete onboarding activities. | I12: Authenticate candidates using Supabase Authentication and redirect them to the Candidate Dashboard. | J12: Valid credentials accepted. • Invalid credentials rejected. • Session created. • Dashboard displayed. | L12: None | N12: Hassan Farooqi | O12: Dev done
A13: US-012 | B13: Phase 2 -- Digital Hiring & Employee Onboarding | C13: Epic 1: Authentication & Access Management | D13: Authentication & Access Management | E13: User | F13: Critical | G13: 5 | H13: As the System, I want to enforce role-based access control so that each user only accesses authorized features. | I13: The system shall support only three roles: Super Admin Recruiter Candidate (later transitions to Employee) Permissions shall be enforced at both UI and API levels. || Database: Users; Roles; Permissions; AuditLogs | J13: Super Admin accesses all modules. • Recruiter accesses recruitment, onboarding, learning, AI, and reporting. • Candidate accesses only personal onboarding, learning, AI Coach, and profile. • Unauthorized requests return HTTP 403. • Hidden UI elements are not rendered for unauthorized roles. | L13: None | M13: Middleware on all protected endpoints. | N13: Hassan Farooqi | O13: Dev done
A14: US-013 | B14: Phase 2 -- Digital Hiring & Employee Onboarding | C14: Epic 2: Recruiter Dashboard & Candidate Dashboard | D14: Dashboard Management | E14: Recruiter | F14: Critical | G14: 5 | H14: As a Recruiter, I want to view a centralized dashboard so that I can monitor onboarding progress, pending approvals, and employee activities. | I14: The system shall provide a dashboard displaying onboarding statistics, pending approvals, recently joined employees, pending document verification, upcoming joining dates, notifications, and quick action shortcuts. || Business Value: Provides recruiters with an overview of onboarding operations, reducing manual tracking and improving operational efficiency. || Preconditions: Recruiter is authenticated.; Dashboard data is available. || Main Flow: Recruiter logs in.; Dashboard loads.; System retrieves onboarding metrics.; Dashboard widgets are displayed. || Database: Dashboard Aggregation Collections; Employees; Documents; Notifications; AuditLogs | J14: Dashboard loads within 3 seconds. • Active employee count displayed. • Pending onboarding displayed. • Pending document verification displayed. • Upcoming joining dates displayed. • Notifications displayed. • Quick actions available. | K14: Dashboard data refreshes every 60 seconds. • Widgets depend on recruiter permissions. | L14: None | M14: GET `/api/dashboard/summary` • GET `/api/dashboard/activity` | N14: Taha Iftikhar
A15: US-014 | B15: Phase 2 -- Digital Hiring & Employee Onboarding | C15: Epic 2: Recruiter Dashboard & Candidate Dashboard | D15: Dashboard Management | E15: Recruiter | F15: High | G15: 3 | H15: As a Recruiter, I want to receive notifications so that I never miss onboarding activities requiring attention. | I15: Display real-time notifications for document submissions, approvals, rejected documents, onboarding completion, and candidate activities. | J15: Notification badge updates. • Unread count displayed. • Notifications marked as read. • Clicking notification redirects to related screen. | L15: None | M15: GET `/api/notifications` • PUT `/api/notifications/read` | N15: Taha Iftikhar
A16: US-015 | B16: Phase 2 -- Digital Hiring & Employee Onboarding | C16: Epic 2: Recruiter Dashboard & Candidate Dashboard | D16: Dashboard Management | E16: User | F16: Medium | G16: 2 | H16: As a Recruiter, I want quick CURD actions so that I can perform common onboarding tasks efficiently. | I16: Provide one-click access to frequently used actions. || Quick Actions: Add Employee; View Documents; Pending Approvals; Candidate List; Reports; Learning Assignments | J16: Buttons visible. • Redirect correctly. • Permission controlled. | L16: None | N16: Sadaf Ashfaq
A17: US-016 | B17: Phase 2 -- Digital Hiring & Employee Onboarding | C17: Epic 2: Recruiter Dashboard & Candidate Dashboard | D17: Dashboard Management | E17: User | F17: Medium | G17: 3 | H17: As a Recruiter, I want to view recent platform activities so that I can track employee onboarding events. | I17: Display chronological activities including: Candidate Registered Documents Uploaded OCR Completed Employee Created Learning Assigned Documents Approved Offer Accepted | J17: Latest activity first. • Timestamp displayed. • User responsible displayed. • Filter available. | L17: None | M17: GET `/api/activity` | N17: Sadaf Ashfaq
A18: US-017 | B18: Phase 2 -- Digital Hiring & Employee Onboarding | C18: Epic 2: Recruiter Dashboard & Candidate Dashboard | D18: Dashboard Management | E18: User | F18: High | G18: 5 | H18: As a Recruiter, I want to search employees and candidates from anywhere in the application. | I18: Provide a universal search allowing recruiters to search using: Name Email Employee ID Candidate ID Department Phone Number Search shall support fuzzy matching using MongoDB Atlas Search. | J18: Results returned within 2 seconds. • Partial keyword supported. • No duplicate results. • Pagination supported. | L18: None | M18: GET `/api/search` | N18: Faris Dosani
A19: US-018 | B19: Phase 2 -- Digital Hiring & Employee Onboarding | C19: Epic 2: Recruiter Dashboard & Candidate Dashboard | D19: Dashboard Management | E19: Candidate | F19: Critical | G19: 5 | H19: As a Candidate, I want a personalized dashboard so that I know what onboarding tasks remain before joining. | I19: Candidate dashboard shall display onboarding progress, pending documents, completed tasks, announcements, learning assignments, and AI Assistant shortcuts. || UI: Progress Bar; Cards; Checklist; Announcements; Learning Widget; AI Assistant Widget | J19: Dashboard displays • Welcome message • Progress bar • Pending documents • Pending signatures • Assigned learning • Announcements • Profile completion percentage | L19: None | N19: Syed Omer Ahmed Shamsi
A20: US-019 | B20: Phase 2 -- Digital Hiring & Employee Onboarding | C20: Epic 2: Recruiter Dashboard & Candidate Dashboard | D20: Dashboard Management | E20: User | F20: Critical | G20: 5 | H20: As a Candidate, I want to track my onboarding completion so that I know what tasks remain before becoming an employee. | I20: The platform shall display onboarding completion percentage based on completed activities. Example ✔ Account Created ✔ Documents Uploaded ✔ OCR Verified ✔ NDA Signed ✔ Offer Accepted ✔ Learning Assigned | J20: Percentage updates automatically. • Completed tasks highlighted. • Pending tasks clickable. | L20: None | M20: GET `/api/onboarding/progress` | N20: Syed Omer Ahmed Shamsi
A21: US-020 | B21: Phase 2 -- Digital Hiring & Employee Onboarding | C21: Epic 2: Recruiter Dashboard & Candidate Dashboard | D21: Dashboard Management | E21: User | F21: Medium | G21: 2 | H21: As a Candidate, I want to receive announcements so that I stay informed about onboarding activities and company updates. | I21: Recruiters can publish onboarding announcements visible to all assigned candidates. | J21: Latest announcements first. • Rich text supported. • Attachments supported. • Read status maintained. | L21: None | N21: Faris Dosani
A22: US-021 | B22: Phase 2 -- Digital Hiring & Employee Onboarding | C22: Epic 2: Recruiter Dashboard & Candidate Dashboard | D22: Dashboard Management | E22: User | F22: High | G22: 3 | H22: As a Candidate, I want to see all pending onboarding tasks in one place so that I can complete them efficiently. | I22: The dashboard shall display all required onboarding activities. Tasks include Upload CNIC Upload Degree Upload Certificates Sign NDA Complete Profile Complete Bank Details Review Policies Complete Assigned Learning | J22: Tasks sorted by priority. • Due dates displayed. • Completion status visible. • Clicking task opens relevant page. | L22: None | N22: Hassan Farooqi
A23: US-022 | B23: Phase 2 -- Digital Hiring & Employee Onboarding | C23: Epic 2: Recruiter Dashboard & Candidate Dashboard | D23: Dashboard Management | E23: User | F23: Low | G23: 2 | H23: As a Candidate, I want my dashboard to greet me personally so that my onboarding experience feels engaging. | I23: Dashboard displays: Welcome message Profile picture Joining date Recruiter contact Department Designation Office location | J23: Data retrieved from employee profile. • Responsive layout. • Information updated automatically. | L23: None | N23: Hassan Farooqi
A24: US-023 | B24: Phase 2 -- Digital Hiring & Employee Onboarding | C24: Epic 3: Employee Profile Management | D24: Employee Profile Management | E24: Recruiter | F24: Critical | G24: 8 | H24: As a Recruiter, I want to convert a selected candidate into an employee so that they become part of the organization's workforce. | I24: Once all onboarding prerequisites are completed (offer acceptance, document verification, approvals, and digital signature), the system shall convert the candidate profile into an employee profile without duplicating data. The candidate status shall automatically change to Employee, and all onboarding information shall be retained. || Business Value: Automates employee creation while preserving the candidate's recruitment history. || Preconditions: Candidate accepted offer.; Required documents verified.; NDA signed.; HR approval completed. || Main Flow: Recruiter opens Candidate Profile.; Reviews onboarding status.; Clicks Convert to Employee.; System validates prerequisites.; Employee profile created.; Candidate status updated.; Employee ID generated.; Confirmation displayed. || Database: Candidates; Employees; AuditLogs | J24: Candidate successfully converted. • No duplicate records created. • Recruitment history retained. • Employee profile generated. • Employee appears in Employee Directory. | K24: Conversion allowed only once. • Mandatory onboarding tasks must be completed. • Audit log created. | L24: None | M24: `POST /api/employees/create-from-candidate` | N24: Aimen Abdullah
A25: US-024 | B25: Phase 2 -- Digital Hiring & Employee Onboarding | C25: Epic 3: Employee Profile Management | D25: Employee Profile Management | E25: User | F25: High | G25: 3 | H25: As a Recruiter, I want the system to automatically generate a unique Employee ID. | I25: The system shall generate a unique employee identifier based on configurable organizational rules. | J25: Employee ID unique. • Generated automatically. • Non-editable. • Searchable. | K25: Example format: • ``` • MZK-2026-000123 • ``` | L25: None | M25: `POST /api/employees/generate-id` | N25: Aimen Abdullah
A26: US-025 | B26: Phase 2 -- Digital Hiring & Employee Onboarding | C26: Epic 3: Employee Profile Management | D26: Employee Profile Management | E26: User | F26: Critical | G26: 5 | H26: As a Candidate, I want to complete my personal information so that my employee record is accurate. | I26: The employee profile shall store: First Name Last Name Date of Birth Gender Nationality Marital Status Blood Group CNIC/Passport Profile Picture | J26: Mandatory fields validated. • Profile saved. • Profile editable. • Audit history maintained. | L26: None | M26: `PUT /api/employees/profile/personal` | N26: Faris Dosani
A27: US-026 | B27: Phase 2 -- Digital Hiring & Employee Onboarding | C27: Epic 3: Employee Profile Management | D27: Employee Profile Management | E27: User | F27: High | G27: 3 | H27: As a Candidate, I want to provide my contact information so that the organization can communicate with me. | I27: Store: Email Phone Alternate Phone Current Address Permanent Address City Country Postal Code | J27: Address validated. • Phone format validated. • Duplicate email prevented. | L27: None | N27: Faris Dosani
A28: US-027 | B28: Phase 2 -- Digital Hiring & Employee Onboarding | C28: Epic 3: Employee Profile Management | D28: Employee Profile Management | E28: User | F28: Medium | G28: 3 | H28: As a Candidate, I want to add emergency contact details so that the company can contact my family in emergencies. | I28: Capture: Contact Name Relationship Phone Number Alternate Number Address | J28: At least one emergency contact required. • Phone validation. • Relationship mandatory. | L28: None | N28: Syed Omer Ahmed Shamsi
A29: US-028 | B29: Phase 2 -- Digital Hiring & Employee Onboarding | C29: Epic 3: Employee Profile Management | D29: Employee Profile Management | E29: User | F29: Medium | G29: 5 | H29: As a Candidate, I want to record my educational qualifications. | I29: Allow multiple education entries. Each entry includes: Degree Institute Board/University CGPA/Percentage Passing Year Major Transcript Upload || Database: Education Collection | J29: Multiple records supported. • Transcript upload optional. • Edit/Delete available. | L29: None | N29: Syed Omer Ahmed Shamsi
A30: US-029 | B30: Phase 2 -- Digital Hiring & Employee Onboarding | C30: Epic 3: Employee Profile Management | D30: Employee Profile Management | E30: User | F30: Medium | G30: 5 | H30: As a Candidate, I want to record my previous employment history. | I30: Store previous organizations. Fields: Company Designation Joining Date Leaving Date Responsibilities Experience Letter | J30: Multiple companies supported. • Total experience calculated. • Employment gap identified. | L30: None | N30: Sadaf Ashfaq
A31: US-030 | B31: Phase 2 -- Digital Hiring & Employee Onboarding | C31: Epic 3: Employee Profile Management | D31: Employee Profile Management | E31: User | F31: Medium | G31: 5 | H31: As a Candidate, I want to manage my professional skills and certifications. | I31: Allow adding: Technical Skills Soft Skills Languages Certifications Certification Documents Expiry Date | J31: Searchable skills. • Multiple certificates. • Expiry reminders. | L31: None | N31: Sadaf Ashfaq
A32: US-031 | B32: Phase 2 -- Digital Hiring & Employee Onboarding | C32: Epic 3: Employee Profile Management | D32: Employee Profile Management | E32: User | F32: Critical | G32: 5 | H32: As a Candidate, I want to submit my banking information for salary processing. | I32: Store: Bank Name Account Title IBAN Branch Branch Code Swift Code Sensitive information shall be encrypted. || Security: Encrypt bank information at rest. | J32: IBAN validated. • Duplicate account prevented. • Encryption applied. | L32: None | N32: Aimen Abdullah
A33: US-032 | B33: Phase 2 -- Digital Hiring & Employee Onboarding | C33: Epic 3: Employee Profile Management | D33: Employee Profile Management | E33: User | F33: Critical | G33: 5 | H33: As a Recruiter, I want to assign employment details to a new employee. | I33: Configure: Department Designation Employment Type Joining Date Office Location Reporting Manager Employment Status | J33: Department mandatory. • Joining date required. • Reporting manager selected. • Status defaults to Active. | L33: None | N33: Aimen Abdullah
A34: US-033 | B34: Phase 2 -- Digital Hiring & Employee Onboarding | C34: Epic 3: Employee Profile Management | D34: Employee Profile Management | E34: User | F34: Medium | G34: 3 | H34: As a Candidate, I want to know how complete my profile is before joining. | I34: The system calculates completion percentage based on mandatory profile sections. | J34: Percentage updates automatically. • Missing fields highlighted. • Progress displayed. | L34: None | N34: Taha Iftikhar
A35: US-034 | B35: Phase 2 -- Digital Hiring & Employee Onboarding | C35: Epic 3: Employee Profile Management | D35: Employee Profile Management | E35: User | F35: Medium | G35: 3 | H35: As a Recruiter, I want to view the employee timeline so that I can track important milestones. | I35: Display chronological events: Candidate Created Interview Completed Offer Sent Offer Accepted Documents Uploaded OCR Verified Employee Created Learning Assigned | J35: Chronological order. • Timestamp shown. • User responsible displayed. | L35: None | N35: Taha Iftikhar
A36: US-035 | B36: Phase 2 -- Digital Hiring & Employee Onboarding | C36: Epic 3: Employee Profile Management | D36: Employee Profile Management | E36: User | F36: High | G36: 5 | H36: As a Recruiter, I want to view and search all employees from a centralized directory. | I36: The Employee Directory shall support: Search by Name Employee ID Department Designation Status Joining Date Additional features: Pagination Sorting Filters Export CSV View Profile Edit Profile || Database: Employees; Departments; Designations; AuditLogs; NDAs, versioning, approval workflow, and secure document storage. | J36: Search response \<2 seconds. • Pagination supported. • Filters work independently and together. • Export generates correct data. • Clicking an employee opens the full profile. | L36: None | M36: `GET /api/employees` • `GET /api/employees/{id}` • `PUT /api/employees/{id}` • `GET /api/employees/export` | N36: Hassan Farooqi
A37: US-036 | B37: Phase 2 -- Digital Hiring & Employee Onboarding | C37: Epic 4: Document Management & Verification | D37: Document Management & Verification | E37: Candidate | F37: Critical | G37: 5 | H37: As a Candidate, I want to upload my government-issued identification (CNIC/Passport) so that my identity can be verified before joining the organization. | I37: The system shall allow candidates to upload government-issued identity documents in PDF, JPG, JPEG, or PNG format. Uploaded files shall be securely stored in Supabase Storage and associated with the candidate profile. The system shall initiate OCR processing automatically after upload. || Business Value: Ensures identity verification and compliance with organizational onboarding requirements. || Preconditions: Candidate account active.; Candidate logged in. || Main Flow: Open Documents page.; Select CNIC/Passport.; Upload file.; Validate file type and size.; Upload to Supabase Storage.; Trigger OCR processing.; Update document status. || Database: Documents; Candidates; AuditLogs || Storage: Supabase Storage | J37: Supported file formats accepted. • Maximum file size validated. • Upload completes successfully. • OCR starts automatically. • Document status updated. | K37: Maximum file size: 10 MB. • One active document per category. • Secure cloud storage mandatory. | L37: None | M37: `POST /api/documents/upload` | N37: Hassan Farooqi
A38: US-037 | B38: Phase 2 -- Digital Hiring & Employee Onboarding | C38: Epic 4: Document Management & Verification | D38: Document Management & Verification | E38: Candidate | F38: High | G38: 5 | H38: As a Candidate, I want to upload my educational documents so that my qualifications can be verified. | I38: Candidates shall upload degree certificates, transcripts, and professional certifications. Multiple files shall be supported. | J38: Multiple uploads supported. • File validation performed. • Documents categorized. • Upload history maintained. | L38: None | N38: Sadaf Ashfaq
A39: US-038 | B39: Phase 2 -- Digital Hiring & Employee Onboarding | C39: Epic 4: Document Management & Verification | D39: Document Management & Verification | E39: User | F39: High | G39: 3 | H39: As a Candidate, I want to upload previous employment documents so that my work experience can be verified. | I39: Support uploading: Experience Letter Relieving Letter Salary Certificate Reference Letter | J39: Documents linked to profile. • Preview available. • Download supported. | L39: None | N39: Sadaf Ashfaq
A40: US-039 | B40: Phase 2 -- Digital Hiring & Employee Onboarding | C40: Epic 4: Document Management & Verification | D40: Document Management & Verification | E40: User | F40: Medium | G40: 2 | H40: As a Candidate, I want my documents organized into categories so that they are easy to manage. | I40: The system shall organize uploaded documents into categories: Identity Education Employment Banking Legal Other | J40: Categories displayed. • Filtering available. • Category mandatory during upload. | L40: None | N40: Sadaf Ashfaq
...

Sheet Test Cases
A1: TC ID | B1: Story ID | C1: Module | D1: Test Scenario | E1: Type | F1: Priority | G1: Preconditions | H1: Test Steps | I1: Expected Result | J1: Status
A2: TC-0001 | B2: US-001 | C2: Phase 2 -- Digital Hiring & Employee Onboarding | D2: Recruiter Registration - Verify complete end-to-end flow with valid data | E2: Positive | F2: Critical | G2: Recruiter has access to the registration page. Recruiter does not already have an account. | H2: 1. Open Registration page. 2. Enter Full Name. 3. Enter Company Email. 4. Enter Phone Number. 5. Enter Password. 6. Confirm Password. 7. Accept Terms & Conditions. 8. Click Register. 9. Validate input. 10. Create account. 11. Send verification email. 12. Display success message. | I2: All steps execute successfully; feature completes as described in the user story without errors. | J2: Not Run
A3: TC-0002 | B3: US-001 | C3: Phase 2 -- Digital Hiring & Employee Onboarding | D3: Recruiter Registration - Given valid information, when Register is clicked, then recruiter account is created. | E3: Positive | F3: Critical | G3: Recruiter has access to the registration page. Recruiter does not already have an account. | H3: 1. Set up preconditions: Recruiter has access to the registration page. Recruiter does not already have an account. 2. Perform the action described: "Given valid information, when Register is clicked, then recruiter account is created." 3. Observe system behaviour. | I3: System behaves exactly as specified: Given valid information, when Register is clicked, then recruiter account is created. | J3: Not Run
A4: TC-0003 | B4: US-001 | C4: Phase 2 -- Digital Hiring & Employee Onboarding | D4: Recruiter Registration - Given duplicate email, when Register is clicked, then duplicate email message is displayed. | E4: Negative | F4: Critical | G4: Recruiter has access to the registration page. Recruiter does not already have an account. | H4: 1. Set up preconditions: Recruiter has access to the registration page. Recruiter does not already have an account. 2. Perform the action described: "Given duplicate email, when Register is clicked, then duplicate email message is displayed." 3. Observe system behaviour. | I4: System behaves exactly as specified: Given duplicate email, when Register is clicked, then duplicate email message is displayed. | J4: Not Run
A5: TC-0004 | B5: US-001 | C5: Phase 2 -- Digital Hiring & Employee Onboarding | D5: Recruiter Registration - Given weak password, when Register is clicked, then registration is blocked. | E5: Negative | F5: Critical | G5: Recruiter has access to the registration page. Recruiter does not already have an account. | H5: 1. Set up preconditions: Recruiter has access to the registration page. Recruiter does not already have an account. 2. Perform the action described: "Given weak password, when Register is clicked, then registration is blocked." 3. Observe system behaviour. | I5: System behaves exactly as specified: Given weak password, when Register is clicked, then registration is blocked. | J5: Not Run
A6: TC-0005 | B6: US-001 | C6: Phase 2 -- Digital Hiring & Employee Onboarding | D6: Recruiter Registration - Given successful registration, then verification email is sent. | E6: Positive | F6: Critical | G6: Recruiter has access to the registration page. Recruiter does not already have an account. | H6: 1. Set up preconditions: Recruiter has access to the registration page. Recruiter does not already have an account. 2. Perform the action described: "Given successful registration, then verification email is sent." 3. Observe system behaviour. | I6: System behaves exactly as specified: Given successful registration, then verification email is sent. | J6: Not Run
A7: TC-0006 | B7: US-001 | C7: Phase 2 -- Digital Hiring & Employee Onboarding | D7: Recruiter Registration - Recruiter cannot login until email is verified. | E7: Negative | F7: Critical | G7: Recruiter has access to the registration page. Recruiter does not already have an account. | H7: 1. Set up preconditions: Recruiter has access to the registration page. Recruiter does not already have an account. 2. Perform the action described: "Recruiter cannot login until email is verified." 3. Observe system behaviour. | I7: System behaves exactly as specified: Recruiter cannot login until email is verified. | J7: Not Run
A8: TC-0007 | B8: US-001 | C8: Phase 2 -- Digital Hiring & Employee Onboarding | D8: Recruiter Registration - Business rule enforcement: Company email must be unique. | E8: Negative | F8: Critical | G8: Recruiter has access to the registration page. Recruiter does not already have an account. | H8: 1. Recruiter has access to the registration page. Recruiter does not already have an account. 2. Perform an action that would violate the rule: "Company email must be unique." 3. Submit / confirm the action. | I8: System enforces business rule and prevents violation: Company email must be unique. | J8: Not Run
A9: TC-0008 | B9: US-001 | C9: Phase 2 -- Digital Hiring & Employee Onboarding | D9: Recruiter Registration - Boundary check: Password minimum 8 characters. (value = 8 character) | E9: Boundary | F9: Critical | G9: Recruiter has access to the registration page. Recruiter does not already have an account. | H9: 1. Recruiter has access to the registration page. Recruiter does not already have an account. 2. Attempt the action with the value exactly at the limit (8 character). 3. Attempt the action with the value one unit below the limit. 4. Attempt the action with the value one unit above the limit. | I9: System enforces the rule 'Password minimum 8 characters.' correctly at, below, and above the boundary value. | J9: Not Run
A10: TC-0009 | B10: US-001 | C10: Phase 2 -- Digital Hiring & Employee Onboarding | D10: Recruiter Registration - Business rule enforcement: Password must contain uppercase, lowercase, number, and special character. | E10: Negative | F10: Critical | G10: Recruiter has access to the registration page. Recruiter does not already have an account. | H10: 1. Recruiter has access to the registration page. Recruiter does not already have an account. 2. Perform an action that would violate the rule: "Password must contain uppercase, lowercase, number, and special character." 3. Submit / confirm the action. | I10: System enforces business rule and prevents violation: Password must contain uppercase, lowercase, number, and special character. | J10: Not Run
A11: TC-0010 | B11: US-001 | C11: Phase 2 -- Digital Hiring & Employee Onboarding | D11: Recruiter Registration - Business rule enforcement: Email verification mandatory. | E11: Negative | F11: Critical | G11: Recruiter has access to the registration page. Recruiter does not already have an account. | H11: 1. Recruiter has access to the registration page. Recruiter does not already have an account. 2. Perform an action that would violate the rule: "Email verification mandatory." 3. Submit / confirm the action. | I11: System enforces business rule and prevents violation: Email verification mandatory. | J11: Not Run
A12: TC-0011 | B12: US-001 | C12: Phase 2 -- Digital Hiring & Employee Onboarding | D12: Recruiter Registration - Input validation: Email format validation. | E12: Negative | F12: Critical | G12: Recruiter has access to the registration page. Recruiter does not already have an account. | H12: 1. Recruiter has access to the registration page. Recruiter does not already have an account. 2. Enter data that violates the validation rule: "Email format validation." 3. Submit the form. | I12: System rejects the invalid input and displays an appropriate validation error for: Email format validation. | J12: Not Run
... A1178: TC-1177 | B1178: US-140 | C1178: Phase 5 -- Monitoring & Reporting | D1178: System Configuration & Organization Settings - Access denied for unauthorized role (Candidate) | E1178: Security | F1178: Critical | G1178: Candidate account exists and is authenticated. | H1178: 1. Log in as Candidate. 2. Attempt to access/perform: "System Configuration & Organization Settings". | I1178: System denies access (HTTP 403 / hidden UI) since this feature is restricted to the 'Super Admin' role. | J1178: Not Run

Sheet Traceability Summary
A1: Story ID | B1: Feature / Module | C1: Priority | D1: Total Test Cases | E1: Positive | F1: Negative | G1: Security | H1: Boundary | I1: Not Run | J1: Pass | K1: Fail | L1: Blocked | M1: Pass Rate % | N1: Assigned Developer
A2: US-001 | B2: ='User Stories'!D2 -> Authentication & Access Management | C2: ='User Stories'!F2 -> Critical | D2: =COUNTIF(TestCases[Story ID],$A2) -> 30 | E2: =COUNTIFS(TestCases[Story ID],$A2,TestCases[Type],"Positive") -> 4 | F2: =COUNTIFS(TestCases[Story ID],$A2,TestCases[Type],"Negative") -> 20 | G2: =COUNTIFS(TestCases[Story ID],$A2,TestCases[Type],"Security") -> 4 | H2: =COUNTIFS(TestCases[Story ID],$A2,TestCases[Type],"Boundary") -> 2 | I2: =COUNTIFS(TestCases[Story ID],$A2,TestCases[Status],"Not Run") -> 30 | J2: =COUNTIFS(TestCases[Story ID],$A2,TestCases[Status],"Pass") -> 0 | K2: =COUNTIFS(TestCases[Story ID],$A2,TestCases[Status],"Fail") -> 0 | L2: =COUNTIFS(TestCases[Story ID],$A2,TestCases[Status],"Blocked") -> 0 | M2: =IF($D2=0,0,$J2/$D2) -> 0 | N2: ='User Stories'!N2 -> Syed Omer Ahmed Shamsi
A3: US-002 | B3: ='User Stories'!D3 -> Authentication & Access Management | C3: ='User Stories'!F3 -> Critical | D3: =COUNTIF(TestCases[Story ID],$A3) -> 14 | E3: =COUNTIFS(TestCases[Story ID],$A3,TestCases[Type],"Positive") -> 4 | F3: =COUNTIFS(TestCases[Story ID],$A3,TestCases[Type],"Negative") -> 6 | G3: =COUNTIFS(TestCases[Story ID],$A3,TestCases[Type],"Security") -> 3 | H3: =COUNTIFS(TestCases[Story ID],$A3,TestCases[Type],"Boundary") -> 1 | I3: =COUNTIFS(TestCases[Story ID],$A3,TestCases[Status],"Not Run") -> 14 | J3: =COUNTIFS(TestCases[Story ID],$A3,TestCases[Status],"Pass") -> 0 | K3: =COUNTIFS(TestCases[Story ID],$A3,TestCases[Status],"Fail") -> 0 | L3: =COUNTIFS(TestCases[Story ID],$A3,TestCases[Status],"Blocked") -> 0 | M3: =IF($D3=0,0,$J3/$D3) -> 0 | N3: ='User Stories'!N3 -> Syed Omer Ahmed Shamsi
A4: US-003 | B4: ='User Stories'!D4 -> Authentication & Access Management | C4: ='User Stories'!F4 -> Medium | D4: =COUNTIF(TestCases[Story ID],$A4) -> 10 | E4: =COUNTIFS(TestCases[Story ID],$A4,TestCases[Type],"Positive") -> 4 | F4: =COUNTIFS(TestCases[Story ID],$A4,TestCases[Type],"Negative") -> 3 | G4: =COUNTIFS(TestCases[Story ID],$A4,TestCases[Type],"Security") -> 3 | H4: =COUNTIFS(TestCases[Story ID],$A4,TestCases[Type],"Boundary") -> 0 | I4: =COUNTIFS(TestCases[Story ID],$A4,TestCases[Status],"Not Run") -> 10 | J4: =COUNTIFS(TestCases[Story ID],$A4,TestCases[Status],"Pass") -> 0 | K4: =COUNTIFS(TestCases[Story ID],$A4,TestCases[Status],"Fail") -> 0 | L4: =COUNTIFS(TestCases[Story ID],$A4,TestCases[Status],"Blocked") -> 0 | M4: =IF($D4=0,0,$J4/$D4) -> 0 | N4: ='User Stories'!N4 -> Taha Iftikhar
A5: US-004 | B5: ='User Stories'!D5 -> Authentication & Access Management | C5: ='User Stories'!F5 -> Critical | D5: =COUNTIF(TestCases[Story ID],$A5) -> 12 | E5: =COUNTIFS(TestCases[Story ID],$A5,TestCases[Type],"Positive") -> 4 | F5: =COUNTIFS(TestCases[Story ID],$A5,TestCases[Type],"Negative") -> 4 | G5: =COUNTIFS(TestCases[Story ID],$A5,TestCases[Type],"Security") -> 3 | H5: =COUNTIFS(TestCases[Story ID],$A5,TestCases[Type],"Boundary") -> 1 | I5: =COUNTIFS(TestCases[Story ID],$A5,TestCases[Status],"Not Run") -> 12 | J5: =COUNTIFS(TestCases[Story ID],$A5,TestCases[Status],"Pass") -> 0 | K5: =COUNTIFS(TestCases[Story ID],$A5,TestCases[Status],"Fail") -> 0 | L5: =COUNTIFS(TestCases[Story ID],$A5,TestCases[Status],"Blocked") -> 0 | M5: =IF($D5=0,0,$J5/$D5) -> 0 | N5: ='User Stories'!N5 -> Taha Iftikhar
A6: US-005 | B6: ='User Stories'!D6 -> Authentication & Access Management | C6: ='User Stories'!F6 -> Medium | D6: =COUNTIF(TestCases[Story ID],$A6) -> 6 | E6: =COUNTIFS(TestCases[Story ID],$A6,TestCases[Type],"Positive") -> 2 | F6: =COUNTIFS(TestCases[Story ID],$A6,TestCases[Type],"Negative") -> 1 | G6: =COUNTIFS(TestCases[Story ID],$A6,TestCases[Type],"Security") -> 3 | H6: =COUNTIFS(TestCases[Story ID],$A6,TestCases[Type],"Boundary") -> 0 | I6: =COUNTIFS(TestCases[Story ID],$A6,TestCases[Status],"Not Run") -> 6 | J6: =COUNTIFS(TestCases[Story ID],$A6,TestCases[Status],"Pass") -> 0 | K6: =COUNTIFS(TestCases[Story ID],$A6,TestCases[Status],"Fail") -> 0 | L6: =COUNTIFS(TestCases[Story ID],$A6,TestCases[Status],"Blocked") -> 0 | M6: =IF($D6=0,0,$J6/$D6) -> 0 | N6: ='User Stories'!N6 -> Sadaf Ashfaq
A7: US-006 | B7: ='User Stories'!D7 -> Authentication & Access Management | C7: ='User Stories'!F7 -> High | D7: =COUNTIF(TestCases[Story ID],$A7) -> 9 | E7: =COUNTIFS(TestCases[Story ID],$A7,TestCases[Type],"Positive") -> 5 | F7: =COUNTIFS(TestCases[Story ID],$A7,TestCases[Type],"Negative") -> 1 | G7: =COUNTIFS(TestCases[Story ID],$A7,TestCases[Type],"Security") -> 3 | H7: =COUNTIFS(TestCases[Story ID],$A7,TestCases[Type],"Boundary") -> 0 | I7: =COUNTIFS(TestCases[Story ID],$A7,TestCases[Status],"Not Run") -> 9 | J7: =COUNTIFS(TestCases[Story ID],$A7,TestCases[Status],"Pass") -> 0 | K7: =COUNTIFS(TestCases[Story ID],$A7,TestCases[Status],"Fail") -> 0 | L7: =COUNTIFS(TestCases[Story ID],$A7,TestCases[Status],"Blocked") -> 0 | M7: =IF($D7=0,0,$J7/$D7) -> 0 | N7: ='User Stories'!N7 -> Sadaf Ashfaq
A8: US-007 | B8: ='User Stories'!D8 -> Authentication & Access Management | C8: ='User Stories'!F8 -> High | D8: =COUNTIF(TestCases[Story ID],$A8) -> 7 | E8: =COUNTIFS(TestCases[Story ID],$A8,TestCases[Type],"Positive") -> 4 | F8: =COUNTIFS(TestCases[Story ID],$A8,TestCases[Type],"Negative") -> 0 | G8: =COUNTIFS(TestCases[Story ID],$A8,TestCases[Type],"Security") -> 3 | H8: =COUNTIFS(TestCases[Story ID],$A8,TestCases[Type],"Boundary") -> 0 | I8: =COUNTIFS(TestCases[Story ID],$A8,TestCases[Status],"Not Run") -> 7 | J8: =COUNTIFS(TestCases[Story ID],$A8,TestCases[Status],"Pass") -> 0 | K8: =COUNTIFS(TestCases[Story ID],$A8,TestCases[Status],"Fail") -> 0 | L8: =COUNTIFS(TestCases[Story ID],$A8,TestCases[Status],"Blocked") -> 0 | M8: =IF($D8=0,0,$J8/$D8) -> 0 | N8: ='User Stories'!N8 -> Faris Dosani
A9: US-008 | B9: ='User Stories'!D9 -> Authentication & Access Management | C9: ='User Stories'!F9 -> Medium | D9: =COUNTIF(TestCases[Story ID],$A9) -> 7 | E9: =COUNTIFS(TestCases[Story ID],$A9,TestCases[Type],"Positive") -> 4 | F9: =COUNTIFS(TestCases[Story ID],$A9,TestCases[Type],"Negative") -> 0 | G9: =COUNTIFS(TestCases[Story ID],$A9,TestCases[Type],"Security") -> 3 | H9: =COUNTIFS(TestCases[Story ID],$A9,TestCases[Type],"Boundary") -> 0 | I9: =COUNTIFS(TestCases[Story ID],$A9,TestCases[Status],"Not Run") -> 7 | J9: =COUNTIFS(TestCases[Story ID],$A9,TestCases[Status],"Pass") -> 0 | K9: =COUNTIFS(TestCases[Story ID],$A9,TestCases[Status],"Fail") -> 0 | L9: =COUNTIFS(TestCases[Story ID],$A9,TestCases[Status],"Blocked") -> 0 | M9: =IF($D9=0,0,$J9/$D9) -> 0 | N9: ='User Stories'!N9 -> Faris Dosani
A10: US-009 | B10: ='User Stories'!D10 -> Authentication & Access Management | C10: ='User Stories'!F10 -> Medium | D10: =COUNTIF(TestCases[Story ID],$A10) -> 7 | E10: =COUNTIFS(TestCases[Story ID],$A10,TestCases[Type],"Positive") -> 3 | F10: =COUNTIFS(TestCases[Story ID],$A10,TestCases[Type],"Negative") -> 1 | G10: =COUNTIFS(TestCases[Story ID],$A10,TestCases[Type],"Security") -> 3 | H10: =COUNTIFS(TestCases[Story ID],$A10,TestCases[Type],"Boundary") -> 0 | I10: =COUNTIFS(TestCases[Story ID],$A10,TestCases[Status],"Not Run") -> 7 | J10: =COUNTIFS(TestCases[Story ID],$A10,TestCases[Status],"Pass") -> 0 | K10: =COUNTIFS(TestCases[Story ID],$A10,TestCases[Status],"Fail") -> 0 | L10: =COUNTIFS(TestCases[Story ID],$A10,TestCases[Status],"Blocked") -> 0 | M10: =IF($D10=0,0,$J10/$D10) -> 0 | N10: ='User Stories'!N10 -> Aimen Abdullah
A11: US-010 | B11: ='User Stories'!D11 -> Authentication & Access Management | C11: ='User Stories'!F11 -> Critical | D11: =COUNTIF(TestCases[Story ID],$A11) -> 8 | E11: =COUNTIFS(TestCases[Story ID],$A11,TestCases[Type],"Positive") -> 4 | F11: =COUNTIFS(TestCases[Story ID],$A11,TestCases[Type],"Negative") -> 1 | G11: =COUNTIFS(TestCases[Story ID],$A11,TestCases[Type],"Security") -> 3 | H11: =COUNTIFS(TestCases[Story ID],$A11,TestCases[Type],"Boundary") -> 0 | I11: =COUNTIFS(TestCases[Story ID],$A11,TestCases[Status],"Not Run") -> 8 | J11: =COUNTIFS(TestCases[Story ID],$A11,TestCases[Status],"Pass") -> 0 | K11: =COUNTIFS(TestCases[Story ID],$A11,TestCases[Status],"Fail") -> 0 | L11: =COUNTIFS(TestCases[Story ID],$A11,TestCases[Status],"Blocked") -> 0 | M11: =IF($D11=0,0,$J11/$D11) -> 0 | N11: ='User Stories'!N11 -> Aimen Abdullah
A12: US-011 | B12: ='User Stories'!D12 -> Authentication & Access Management | C12: ='User Stories'!F12 -> Critical | D12: =COUNTIF(TestCases[Story ID],$A12) -> 7 | E12: =COUNTIFS(TestCases[Story ID],$A12,TestCases[Type],"Positive") -> 3 | F12: =COUNTIFS(TestCases[Story ID],$A12,TestCases[Type],"Negative") -> 1 | G12: =COUNTIFS(TestCases[Story ID],$A12,TestCases[Type],"Security") -> 3 | H12: =COUNTIFS(TestCases[Story ID],$A12,TestCases[Type],"Boundary") -> 0 | I12: =COUNTIFS(TestCases[Story ID],$A12,TestCases[Status],"Not Run") -> 7 | J12: =COUNTIFS(TestCases[Story ID],$A12,TestCases[Status],"Pass") -> 0 | K12: =COUNTIFS(TestCases[Story ID],$A12,TestCases[Status],"Fail") -> 0 | L12: =COUNTIFS(TestCases[Story ID],$A12,TestCases[Status],"Blocked") -> 0 | M12: =IF($D12=0,0,$J12/$D12) -> 0 | N12: ='User Stories'!N12 -> Hassan Farooqi
A13: US-012 | B13: ='User Stories'!D13 -> Authentication & Access Management | C13: ='User Stories'!F13 -> Critical | D13: =COUNTIF(TestCases[Story ID],$A13) -> 12 | E13: =COUNTIFS(TestCases[Story ID],$A13,TestCases[Type],"Positive") -> 4 | F13: =COUNTIFS(TestCases[Story ID],$A13,TestCases[Type],"Negative") -> 4 | G13: =COUNTIFS(TestCases[Story ID],$A13,TestCases[Type],"Security") -> 4 | H13: =COUNTIFS(TestCases[Story ID],$A13,TestCases[Type],"Boundary") -> 0 | I13: =COUNTIFS(TestCases[Story ID],$A13,TestCases[Status],"Not Run") -> 12 | J13: =COUNTIFS(TestCases[Story ID],$A13,TestCases[Status],"Pass") -> 0 | K13: =COUNTIFS(TestCases[Story ID],$A13,TestCases[Status],"Fail") -> 0 | L13: =COUNTIFS(TestCases[Story ID],$A13,TestCases[Status],"Blocked") -> 0 | M13: =IF($D13=0,0,$J13/$D13) -> 0 | N13: ='User Stories'!N13 -> Hassan Farooqi
... A141: US-140 | B141: ='User Stories'!D141 -> Reporting, Analytics & Executive Dashboards | C141: ='User Stories'!F141 -> Critical | D141: =COUNTIF(TestCases[Story ID],$A141) -> 15 | E141: =COUNTIFS(TestCases[Story ID],$A141,TestCases[Type],"Positive") -> 7 | F141: =COUNTIFS(TestCases[Story ID],$A141,TestCases[Type],"Negative") -> 4 | G141: =COUNTIFS(TestCases[Story ID],$A141,TestCases[Type],"Security") -> 4 | H141: =COUNTIFS(TestCases[Story ID],$A141,TestCases[Type],"Boundary") -> 0 | I141: =COUNTIFS(TestCases[Story ID],$A141,TestCases[Status],"Not Run") -> 15 | J141: =COUNTIFS(TestCases[Story ID],$A141,TestCases[Status],"Pass") -> 0 | K141: =COUNTIFS(TestCases[Story ID],$A141,TestCases[Status],"Fail") -> 0 | L141: =COUNTIFS(TestCases[Story ID],$A141,TestCases[Status],"Blocked") -> 0 | M141: =IF($D141=0,0,$J141/$D141) -> 0 | N141: ='User Stories'!N141 -> 0
B143: TOTALS | D143: =SUM(D2:D141) -> 1177 | E143: =SUM(E2:E141) -> 539 | F143: =SUM(F2:F141) -> 201 | G143: =SUM(G2:G141) -> 430 | H143: =SUM(H2:H141) -> 7 | I143: =SUM(I2:I141) -> 1177 | J143: =SUM(J2:J141) -> 0 | K143: =SUM(K2:K141) -> 0 | L143: =SUM(L2:L141) -> 0 | M143: =IF(D143=0,0,J143/D143) -> 0

Sheet Team Members
A1: Developer / QA Name | B1: Role | C1: Notes
A2: Hassan Farooqi
A3: Taha Iftikhar
A4: Faris Dosani
A5: Syed Omer Ahmed Shamsi
A6: Sadaf Ashfaq
A7: Aimen Abdullah
